<?xml version="1.0"?>
<robot name="delivery_bot" xmlns:xacro="http://ros.org/wiki/xacro">

  <!-- Chassis -->
  <link name="base_link">
    <visual>
      <geometry>
        <box size="0.6969 0.55639 0.2"/>
      </geometry>
      <origin xyz="0 0 0.23652" rpy="0 0 0"/>
      <material name="grey">
        <color rgba="0.6 0.6 0.6 1.0"/>
      </material>
    </visual>
    <collision>
      <geometry>
        <box size="0.6969 0.55639 0.2"/>
      </geometry>
      <origin xyz="0 0 0.23652" rpy="0 0 0"/>
    </collision>
    <inertial>
      <mass value="10.0"/>
      <inertia ixx="0.5" ixy="0.0" ixz="0.0" iyy="0.5" iyz="0.0" izz="0.5"/>
      <origin xyz="0 0 0.23652"/>
    </inertial>
  </link>

  <!-- LIDAR -->
  <link name="laser_link">
    <visual>
      <geometry>
        <cylinder radius="0.03" length="0.038"/>
      </geometry>
      <origin xyz="0 0 0.35652" rpy="0 0 0"/>
      <material name="blue">
        <color rgba="0.0 0.0 1.0 1.0"/>
      </material>
    </visual>
    <collision>
      <geometry>
        <cylinder radius="0.03" length="0.038"/>
      </geometry>
      <origin xyz="0 0 0.35652" rpy="0 0 0"/>
    </collision>
    <inertial>
      <mass value="0.2"/>
      <inertia ixx="0.001" ixy="0.0" ixz="0.0" iyy="0.001" iyz="0.0" izz="0.001"/>
      <origin xyz="0 0 0.35652"/>
    </inertial>
  </link>

  <joint name="laser_joint" type="fixed">
    <parent link="base_link"/>
    <child link="laser_link"/>
    <origin xyz="0 0 0.01" rpy="0 0 0"/>
  </joint>

  <!-- IMU -->
  <link name="imu_link">
    <visual>
      <geometry>
        <box size="0.05 0.02 0.02"/>
      </geometry>
      <origin xyz="0 0 0.3" rpy="0 0 0"/>
      <material name="green">
        <color rgba="0.0 1.0 0.0 1.0"/>
      </material>
    </visual>
    <collision>
      <geometry>
        <box size="0.05 0.02 0.02"/>
      </geometry>
      <origin xyz="0 0 0.3" rpy="0 0 0"/>
    </collision>
    <inertial>
      <mass value="0.1"/>
      <inertia ixx="0.0001" ixy="0.0" ixz="0.0" iyy="0.0001" iyz="0.0" izz="0.0001"/>
      <origin xyz="0 0 0.3"/>
    </inertial>
  </link>

  <joint name="imu_joint" type="fixed">
    <parent link="base_link"/>
    <child link="imu_link"/>
    <origin xyz="0 0 0" rpy="0 0 0"/>
  </joint>

  <!-- Wheels (Links + Collisions + Inertials) -->
  <xacro:macro name="wheel" params="name">
    <link name="${name}">
      <visual>
        <geometry>
          <cylinder radius="0.09652" length="0.022"/>
        </geometry>
        <origin xyz="0 0 0" rpy="1.5708 0 0"/>
        <material name="black">
          <color rgba="0.1 0.1 0.1 1.0"/>
        </material>
      </visual>
      <collision>
        <geometry>
          <cylinder radius="0.09652" length="0.022"/>
        </geometry>
        <origin xyz="0 0 0" rpy="1.5708 0 0"/>
      </collision>
      <inertial>
        <mass value="1.0"/>
        <inertia ixx="0.01" ixy="0.0" ixz="0.0" iyy="0.01" iyz="0.0" izz="0.01"/>
        <origin xyz="0 0 0"/>
      </inertial>
    </link>
  </xacro:macro>

  <xacro:wheel name="left_front_wheel"/>
  <xacro:wheel name="left_rear_wheel"/>
  <xacro:wheel name="right_front_wheel"/>
  <xacro:wheel name="right_rear_wheel"/>

  <!-- Wheel Joints -->
  <joint name="left_front_joint" type="continuous">
    <parent link="base_link"/>
    <child link="left_front_wheel"/>
    <origin xyz="0.30 0.32 0.09652" rpy="0 0 0"/>
    <axis xyz="0 1 0"/>
  </joint>

  <joint name="left_rear_joint" type="continuous">
    <parent link="base_link"/>
    <child link="left_rear_wheel"/>
    <origin xyz="-0.30 0.32 0.09652" rpy="0 0 0"/>
    <axis xyz="0 1 0"/>
  </joint>

  <joint name="right_front_joint" type="continuous">
    <parent link="base_link"/>
    <child link="right_front_wheel"/>
    <origin xyz="0.30 -0.32 0.09652" rpy="0 0 0"/>
    <axis xyz="0 1 0"/>
  </joint>

  <joint name="right_rear_joint" type="continuous">
    <parent link="base_link"/>
    <child link="right_rear_wheel"/>
    <origin xyz="-0.30 -0.32 0.09652" rpy="0 0 0"/>
    <axis xyz="0 1 0"/>
  </joint>

</robot>